Workbook

Sheet environmental_data
A1: Date | B1: Strain | C1: Ankyrin? | D1: Temp_ºC | E1: PSU | F1: pH
A2: 45881 | B2: Hal281 | C2: No | D2: 17.7 | E2: 12.1 | F2: 8.186
A3: 45888 | B3: M60M31 | C3: No | D3: 19.6 | E3: 14.5 | F3: 8.3
A4: 45890 | B4: SA48 | C4: No | D4: 17.5 | E4: 14.3 | F4: 8.3
A5: 45891 | B5: Hal054 | C5: Yes | D5: 18 | E5: 14.6 | F5: 8.258
A6: 45896 | B6: DMZ507 | C6: No | D6: 18.6 | E6: 14.8 | F6: 8.24
A7: 45898 | B7: M60M70 | C7: Yes | D7: 18.4 | E7: 14.9 | F7: 8.289
A8: 45910 | B8: Hal281 | C8: No | D8: 18.6 | E8: 16.7 | F8: 7.89

Sheet sponge_size_uptake_noDSM
A1: Date | B1: Sponge | C1: water_temp | D1: water_PSU | E1: water_pH | F1: Weight_g | G1: start_concentration_vibrio_cells/mL | H1: Ankyrin_present | I1: sponge_cells/mL | L1: Mean | M1: SD
A2: 45881 | B2: Hal281-30-1 | C2: 17.7 | D2: 12.1 | E2: 8.186 | F2: =42.281-37.755 -> 4.526 | G2: 1.0*10e6 | H2: 0 | K2: T | L2: =AVERAGE(C:C) -> 18.304762 | M2: =STDEV(C:C) -> 0.70259185
A3: 45881 | B3: Hal281-30-2 | C3: 17.7 | D3: 12.1 | E3: 8.186 | F3: =43.511-37.812 -> 5.699 | G3: 1.0*10e6 | H3: 0 | K3: S | L3: =AVERAGE(D:D) -> 14.514286 | M3: =STDEV(D:D) -> 1.3578267
A4: 45881 | B4: Hal281-30-3 | C4: 17.7 | D4: 12.1 | E4: 8.186 | F4: =50.843-37.598 -> 13.245 | G4: 1.0*10e6 | H4: 0 | K4: pH | L4: =AVERAGE(E:E) -> 8.2026667 | M4: =STDEV(E:E) -> 0.14703968
A5: 45881 | B5: Hal281-60-1 | C5: 17.7 | D5: 12.1 | E5: 8.186 | F5: =42.05-37.537 -> 4.513 | G5: 1.0*10e6 | H5: 0 | K5: Sponge_weight | L5: =AVERAGE(F:F) -> 5.291619 | M5: =STDEV(F:F) -> 1.8349274
A6: 45881 | B6: Hal281-60-2 | C6: 17.7 | D6: 12.1 | E6: 8.186 | F6: =44.23-37.713 -> 6.517 | G6: 1.0*10e6 | H6: 0 | K6: sponge_cells | L6: =AVERAGE(I:I) -> 61194286 | M6: =STDEV(I:I) -> 29537613
A7: 45881 | B7: Hal281-60-3 | C7: 17.7 | D7: 12.1 | E7: 8.186 | F7: =41.92-37.571 -> 4.349 | G7: 1.0*10e6 | H7: 0
A8: 45881 | B8: Control-30-1 | C8: 17.7 | D8: 12.1 | E8: 8.186 | F8: =40.76-37.701 -> 3.059 | G8: NA | H8: NA
A9: 45888 | B9: M60M31-30-1 | C9: 19.6 | D9: 14.5 | E9: 8.3 | F9: 6.527 | G9: 1.0*10e6 | H9: 0 | I9: 36500000
A10: 45888 | B10: M60M31-30-2 | C10: 19.6 | D10: 14.5 | E10: 8.3 | F10: 6.36 | G10: 1.0*10e6 | H10: 0 | I10: 66700000
A11: 45888 | B11: M60M31-30-3 | C11: 19.6 | D11: 14.5 | E11: 8.3 | F11: 3.12 | G11: 1.0*10e6 | H11: 0 | I11: 33000000
A12: 45888 | B12: M60M31-60-1 | C12: 19.6 | D12: 14.5 | E12: 8.3 | F12: 4.424 | G12: 1.0*10e6 | H12: 0 | I12: 26100000
A13: 45888 | B13: M60M31-60-2 | C13: 19.6 | D13: 14.5 | E13: 8.3 | F13: 6.11 | G13: 1.0*10e6 | H13: 0 | I13: 24800000
A14: 45888 | B14: M60M31-60-3 | C14: 19.6 | D14: 14.5 | E14: 8.3 | F14: 7.846 | G14: 1.0*10e6 | H14: 0 | I14: 33200000
A15: 45888 | B15: Control-60-1 | C15: 19.6 | D15: 14.5 | E15: 8.3 | F15: 2.483 | G15: NA | H15: NA | I15: 20300000
A16: 45890 | B16: SA48-30-1 | C16: 17.5 | D16: 14.3 | E16: 8.3 | F16: 6.65 | G16: 1.0*10e6 | H16: 1 | I16: 87500000
A17: 45890 | B17: SA48-30-2 | C17: 17.5 | D17: 14.3 | E17: 8.3 | F17: 5.187 | G17: 1.0*10e6 | H17: 1 | I17: 53300000
A18: 45890 | B18: SA48-30-3 | C18: 17.5 | D18: 14.3 | E18: 8.3 | F18: 7.872 | G18: 1.0*10e6 | H18: 1 | I18: 65100000
A19: 45890 | B19: SA48-60-1 | C19: 17.5 | D19: 14.3 | E19: 8.3 | F19: 5.328 | G19: 1.0*10e6 | H19: 1 | I19: 72800000
A20: 45890 | B20: SA48-60-2 | C20: 17.5 | D20: 14.3 | E20: 8.3 | F20: 3.888 | G20: 1.0*10e6 | H20: 1 | I20: 46400000
A21: 45890 | B21: SA48-60-3 | C21: 17.5 | D21: 14.3 | E21: 8.3 | F21: 5.32 | G21: 1.0*10e6 | H21: 1 | I21: 49100000
A22: 45890 | B22: Control-30-2 | C22: 17.5 | D22: 14.3 | E22: 8.3 | F22: 2.572 | G22: NA | H22: NA | I22: 36300000
A23: 45891 | B23: Hal054-30-1 | C23: 18 | D23: 14.6 | E23: 8.258 | F23: 4.413 | G23: 1.0*10e6 | H23: 1 | I23: 47700000
A24: 45891 | B24: Hal054-30-2 | C24: 18 | D24: 14.6 | E24: 8.258 | F24: 5.4 | G24: 1.0*10e6 | H24: 1 | I24: 66200000
A25: 45891 | B25: Hal054-30-3 | C25: 18 | D25: 14.6 | E25: 8.258 | F25: 5.238 | G25: 1.0*10e6 | H25: 1 | I25: 86000000
A26: 45891 | B26: Hal054-60-1 | C26: 18 | D26: 14.6 | E26: 8.258 | F26: 4.805 | G26: 1.0*10e6 | H26: 1 | I26: 50700000
A27: 45891 | B27: Hal054-60-2 | C27: 18 | D27: 14.6 | E27: 8.258 | F27: 4.566 | G27: 1.0*10e6 | H27: 1 | I27: 42300000
A28: 45891 | B28: Hal054-60-3 | C28: 18 | D28: 14.6 | E28: 8.258 | F28: 4.087 | G28: 1.0*10e6 | H28: 1 | I28: 63700000
A29: 45891 | B29: Control-60-2 | C29: 18 | D29: 14.6 | E29: 8.258 | F29: 5.149 | G29: NA | H29: NA | I29: 51700000
A30: 45896 | B30: Control-60-3 | C30: 18.6 | D30: 14.8 | E30: 8.24 | F30: 4.716 | G30: NA | H30: NA | I30: 63000000
A31: 45898 | B31: M60M70-30-1 | C31: 18.4 | D31: 14.9 | E31: 8.289 | F31: 4.04 | G31: 1.0*10e6 | H31: 1 | I31: 51100000
A32: 45898 | B32: M60M70-30-2 | C32: 18.4 | D32: 14.9 | E32: 8.289 | F32: 6.295 | G32: 1.0*10e6 | H32: 1 | I32: 180000000
A33: 45898 | B33: M60M70-30-3 | C33: 18.4 | D33: 14.9 | E33: 8.289 | F33: 4.145 | G33: 1.0*10e6 | H33: 1 | I33: 74200000
A34: 45898 | B34: M60M70-60-1 | C34: 18.4 | D34: 14.9 | E34: 8.289 | F34: 4.693 | G34: 1.0*10e6 | H34: 1 | I34: 79900000
A35: 45898 | B35: M60M70-60-2 | C35: 18.4 | D35: 14.9 | E35: 8.289 | F35: 4.364 | G35: 1.0*10e6 | H35: 1 | I35: 59800000
A36: 45898 | B36: M60M70-60-3 | C36: 18.4 | D36: 14.9 | E36: 8.289 | F36: 4.396 | G36: 1.0*10e6 | H36: 1 | I36: 53000000
A37: 45910 | B37: Hal281-30-4 | C37: 18.6 | D37: 16.7 | E37: 7.89 | F37: 4.701 | G37: 1.0*10e6 | H37: 0 | I37: 54100000
A38: 45910 | B38: Hal281-30-5 | C38: 18.6 | D38: 16.7 | E38: 7.89 | F38: 7.529 | G38: 1.0*10e6 | H38: 0 | I38: 66600000
A39: 45910 | B39: Hal281-30-6 | C39: 18.6 | D39: 16.7 | E39: 7.89 | F39: 5.739 | G39: 1.0*10e6 | H39: 0 | I39: 119000000
A40: 45910 | B40: Hal281-60-4 | C40: 18.6 | D40: 16.7 | E40: 7.89 | F40: 4.227 | G40: 1.0*10e6 | H40: 0 | I40: 40300000
...

Sheet sponge_size_uptake
A1: Date | B1: Sponge | C1: water_temp | D1: water_PSU | E1: water_pH | F1: weight_g_freshly_cut | G1: Weight_g | H1: Volume_ml | I1: start_concentration_vibrio_cells/mL | J1: Ankyrin_present | K1: sponge_cells/mL | N1: Mean | O1: SD
A2: 45881 | B2: Hal281-30-1 | C2: 17.7 | D2: 12.1 | E2: 8.186 | F2: 5.76 | G2: =42.281-37.755 -> 4.526 | H2: =(1.2*G2)-0.3 -> 5.1312 | I2: 1.0*10e6 | J2: 0 | M2: T | N2: =AVERAGE(C:C) -> 18.330435 | O2: =STDEV(C:C) -> 0.67589268
A3: 45881 | B3: Hal281-30-2 | C3: 17.7 | D3: 12.1 | E3: 8.186 | F3: 6.54 | G3: =43.511-37.812 -> 5.699 | H3: =(1.2*G3)-0.3 -> 6.5388 | I3: 1.0*10e6 | J3: 0 | M3: S | N3: =AVERAGE(D:D) -> 14.53913 | O3: =STDEV(D:D) -> 1.298628
A4: 45881 | B4: Hal281-30-3 | C4: 17.7 | D4: 12.1 | E4: 8.186 | F4: 6.19 | G4: =50.843-37.598 -> 13.245 | H4: =(1.2*G4)-0.3 -> 15.594 | I4: 1.0*10e6 | J4: 0 | M4: pH | N4: =AVERAGE(E:E) -> 8.205913 | O4: =STDEV(E:E) -> 0.14075492
A5: 45881 | B5: Hal281-60-1 | C5: 17.7 | D5: 12.1 | E5: 8.186 | F5: 5.3 | G5: =42.05-37.537 -> 4.513 | H5: =(1.2*G5)-0.3 -> 5.1156 | I5: 1.0*10e6 | J5: 0 | M5: Sponge_weight | N5: =AVERAGE(G:G) -> 5.1435217 | O5: =STDEV(G:G) -> 1.8518609
A6: 45881 | B6: Hal281-60-2 | C6: 17.7 | D6: 12.1 | E6: 8.186 | F6: 6.11 | G6: =44.23-37.713 -> 6.517 | H6: =(1.2*G6)-0.3 -> 7.5204 | I6: 1.0*10e6 | J6: 0 | M6: sponge_cells | N6: =AVERAGE(K:K) -> 59671795 | O6: =STDEV(K:K) -> 28482709
A7: 45881 | B7: Hal281-60-3 | C7: 17.7 | D7: 12.1 | E7: 8.186 | F7: 4.8 | G7: =41.92-37.571 -> 4.349 | H7: =(1.2*G7)-0.3 -> 4.9188 | I7: 1.0*10e6 | J7: 0 | M7: Sponge_volume | N7: =AVERAGE(H2:H47) -> 5.8722261 | O7: =STDEV(H2:H47) -> 2.2222331
A8: 45881 | B8: Control-30-1 | C8: 17.7 | D8: 12.1 | E8: 8.186 | F8: 5.96 | G8: =40.76-37.701 -> 3.059 | H8: =(1.2*G8)-0.3 -> 3.3708 | I8: NA | J8: NA
A9: 45888 | B9: M60M31-30-1 | C9: 19.6 | D9: 14.5 | E9: 8.3 | F9: 6.53 | G9: 6.527 | H9: =(1.2*G9)-0.3 -> 7.5324 | I9: 1.0*10e6 | J9: 0 | K9: 36500000
A10: 45888 | B10: M60M31-30-2 | C10: 19.6 | D10: 14.5 | E10: 8.3 | F10: 5.75 | G10: 6.36 | H10: =(1.2*G10)-0.3 -> 7.332 | I10: 1.0*10e6 | J10: 0 | K10: 66700000
A11: 45888 | B11: M60M31-30-3 | C11: 19.6 | D11: 14.5 | E11: 8.3 | F11: 4.18 | G11: 3.12 | H11: =(1.2*G11)-0.3 -> 3.444 | I11: 1.0*10e6 | J11: 0 | K11: 33000000 | M11: V Hal281 | N11: =AVERAGE(G41:G46) -> 5.587
A12: 45888 | B12: M60M31-60-1 | C12: 19.6 | D12: 14.5 | E12: 8.3 | F12: 5.96 | G12: 4.424 | H12: =(1.2*G12)-0.3 -> 5.0088 | I12: 1.0*10e6 | J12: 0 | K12: 26100000 | M12: VHal054 | N12: =AVERAGE(H23:H28) -> 5.4018
A13: 45888 | B13: M60M31-60-2 | C13: 19.6 | D13: 14.5 | E13: 8.3 | F13: 5.55 | G13: 6.11 | H13: =(1.2*G13)-0.3 -> 7.032 | I13: 1.0*10e6 | J13: 0 | K13: 24800000 | M13: VM30 | N13: =AVERAGE(H9:H14) -> 6.5774
A14: 45888 | B14: M60M31-60-3 | C14: 19.6 | D14: 14.5 | E14: 8.3 | F14: 5.55 | G14: 7.846 | H14: =(1.2*G14)-0.3 -> 9.1152 | I14: 1.0*10e6 | J14: 0 | K14: 33200000 | M14: VSA48 | N14: =AVERAGE(H16:H21) -> 6.549
A15: 45888 | B15: Control-60-1 | C15: 19.6 | D15: 14.5 | E15: 8.3 | F15: NA | G15: 2.483 | H15: =(1.2*G15)-0.3 -> 2.6796 | I15: NA | J15: NA | K15: 20300000 | M15: M70 | N15: =AVERAGE(H35:H40) -> 5.2866
A16: 45890 | B16: SA48-30-1 | C16: 17.5 | D16: 14.3 | E16: 8.3 | F16: 4.76 | G16: 6.65 | H16: =(1.2*G16)-0.3 -> 7.68 | I16: 1.0*10e6 | J16: 1 | K16: 87500000
A17: 45890 | B17: SA48-30-2 | C17: 17.5 | D17: 14.3 | E17: 8.3 | F17: 5.65 | G17: 5.187 | H17: =(1.2*G17)-0.3 -> 5.9244 | I17: 1.0*10e6 | J17: 1 | K17: 53300000
A18: 45890 | B18: SA48-30-3 | C18: 17.5 | D18: 14.3 | E18: 8.3 | F18: 6.8 | G18: 7.872 | H18: =(1.2*G18)-0.3 -> 9.1464 | I18: 1.0*10e6 | J18: 1 | K18: 65100000
A19: 45890 | B19: SA48-60-1 | C19: 17.5 | D19: 14.3 | E19: 8.3 | F19: 6.45 | G19: 5.328 | H19: =(1.2*G19)-0.3 -> 6.0936 | I19: 1.0*10e6 | J19: 1 | K19: 72800000
A20: 45890 | B20: SA48-60-2 | C20: 17.5 | D20: 14.3 | E20: 8.3 | F20: 5.17 | G20: 3.888 | H20: =(1.2*G20)-0.3 -> 4.3656 | I20: 1.0*10e6 | J20: 1 | K20: 46400000
A21: 45890 | B21: SA48-60-3 | C21: 17.5 | D21: 14.3 | E21: 8.3 | F21: 5.64 | G21: 5.32 | H21: =(1.2*G21)-0.3 -> 6.084 | I21: 1.0*10e6 | J21: 1 | K21: 49100000
A22: 45890 | B22: Control-30-2 | C22: 17.5 | D22: 14.3 | E22: 8.3 | F22: 5.81 | G22: 2.572 | H22: =(1.2*G22)-0.3 -> 2.7864 | I22: NA | J22: NA | K22: 36300000
A23: 45891 | B23: Hal054-30-1 | C23: 18 | D23: 14.6 | E23: 8.258 | F23: 5.08 | G23: 4.413 | H23: =(1.2*G23)-0.3 -> 4.9956 | I23: 1.0*10e6 | J23: 1 | K23: 47700000
A24: 45891 | B24: Hal054-30-2 | C24: 18 | D24: 14.6 | E24: 8.258 | F24: 5.96 | G24: 5.4 | H24: =(1.2*G24)-0.3 -> 6.18 | I24: 1.0*10e6 | J24: 1 | K24: 66200000
A25: 45891 | B25: Hal054-30-3 | C25: 18 | D25: 14.6 | E25: 8.258 | F25: 4.57 | G25: 5.238 | H25: =(1.2*G25)-0.3 -> 5.9856 | I25: 1.0*10e6 | J25: 1 | K25: 86000000
A26: 45891 | B26: Hal054-60-1 | C26: 18 | D26: 14.6 | E26: 8.258 | F26: 5.1 | G26: 4.805 | H26: =(1.2*G26)-0.3 -> 5.466 | I26: 1.0*10e6 | J26: 1 | K26: 50700000
A27: 45891 | B27: Hal054-60-2 | C27: 18 | D27: 14.6 | E27: 8.258 | F27: 5.36 | G27: 4.566 | H27: =(1.2*G27)-0.3 -> 5.1792 | I27: 1.0*10e6 | J27: 1 | K27: 42300000
A28: 45891 | B28: Hal054-60-3 | C28: 18 | D28: 14.6 | E28: 8.258 | F28: 4.97 | G28: 4.087 | H28: =(1.2*G28)-0.3 -> 4.6044 | I28: 1.0*10e6 | J28: 1 | K28: 63700000
A29: 45891 | B29: Control-60-2 | C29: 18 | D29: 14.6 | E29: 8.258 | F29: 4.59 | G29: 5.149 | H29: =(1.2*G29)-0.3 -> 5.8788 | I29: NA | J29: NA | K29: 51700000
A30: 45896 | B30: DMZ507-30-1 | C30: 18.6 | D30: 14.8 | E30: 8.24 | F30: 5.82 | G30: 4.036 | H30: =(1.2*G30)-0.3 -> 4.5432 | I30: 1.0*10e6 | J30: 0 | K30: 62000000
A31: 45896 | B31: DMZ507-30-2 | C31: 18.6 | D31: 14.8 | E31: 8.24 | F31: 4.2 | G31: 1.999 | H31: =(1.2*G31)-0.3 -> 2.0988 | I31: 1.0*10e6 | J31: 0 | K31: 38400000
A32: 45896 | B32: DMZ507-60-1 | C32: 18.6 | D32: 14.8 | E32: 8.24 | F32: 6.8 | G32: 3.086 | H32: =(1.2*G32)-0.3 -> 3.4032 | I32: 1.0*10e6 | J32: 0 | K32: 38300000
A33: 45896 | B33: DMZ507-60-2 | C33: 18.6 | D33: 14.8 | E33: 8.24 | F33: 6.9 | G33: 5.233 | H33: =(1.2*G33)-0.3 -> 5.9796 | I33: 1.0*10e6 | J33: 0 | K33: 46700000
A34: 45896 | B34: Control-60-3 | C34: 18.6 | D34: 14.8 | E34: 8.24 | F34: 5.4 | G34: 4.716 | H34: =(1.2*G34)-0.3 -> 5.3592 | I34: NA | J34: NA | K34: 63000000
A35: 45898 | B35: M60M70-30-1 | C35: 18.4 | D35: 14.9 | E35: 8.289 | F35: 6.13 | G35: 4.04 | H35: =(1.2*G35)-0.3 -> 4.548 | I35: 1.0*10e6 | J35: 1 | K35: 51100000
A36: 45898 | B36: M60M70-30-2 | C36: 18.4 | D36: 14.9 | E36: 8.289 | F36: 5.95 | G36: 6.295 | H36: =(1.2*G36)-0.3 -> 7.254 | I36: 1.0*10e6 | J36: 1 | K36: 180000000
A37: 45898 | B37: M60M70-30-3 | C37: 18.4 | D37: 14.9 | E37: 8.289 | F37: 5 | G37: 4.145 | H37: =(1.2*G37)-0.3 -> 4.674 | I37: 1.0*10e6 | J37: 1 | K37: 74200000
A38: 45898 | B38: M60M70-60-1 | C38: 18.4 | D38: 14.9 | E38: 8.289 | F38: 5.53 | G38: 4.693 | H38: =(1.2*G38)-0.3 -> 5.3316 | I38: 1.0*10e6 | J38: 1 | K38: 79900000
A39: 45898 | B39: M60M70-60-2 | C39: 18.4 | D39: 14.9 | E39: 8.289 | F39: 4.29 | G39: 4.364 | H39: =(1.2*G39)-0.3 -> 4.9368 | I39: 1.0*10e6 | J39: 1 | K39: 59800000
A40: 45898 | B40: M60M70-60-3 | C40: 18.4 | D40: 14.9 | E40: 8.289 | F40: 6.71 | G40: 4.396 | H40: =(1.2*G40)-0.3 -> 4.9752 | I40: 1.0*10e6 | J40: 1 | K40: 53000000
...

Sheet strain_info
A1: Strain | B1: Ankyrin | C1: Length | D1: Top_3_BLAST_results_ALL | E1: Precentage_identity | F1: Ascension_number | G1: Top_3_BLAST_results_TYPE | H1: Precentage_identity | I1: Ascension_number
A2: M60_M70 | B2: Y | C2: 1458 | D2: Vibrio diabolicus strain LMG 3418 Vibrio alginolyticus strain AUSMDU00064140 Vibrio diabolicus strain FA3 | E2: 100 100 100 | F2: CP014134.1 CP110670.1 CP042451.1 | G2: Vibrio antiquarius strain EX25 Vibrio alginolyticus NBRC 15630 = ATCC 17749 Vibrio alginolyticus strain NBRC 15630 | H2: 99.86 99.79 99.79 | I2: CP001805.1 CP006718.1 NR_122050.1
A3: M60_M31 | B3: N | C3: 1463 | D3: Vibrio natriegens strain CL-2 Vibrio campbellii strain KJ-W18 Vibrio natriegens NBRC 15636 = ATCC 14048 = DSM 759 | E3: 98.63 98.63 98.63 | F3: CP142837.1 JQ799114.1 CP009977.1 | G3: Vibrio natriegens NBRC 15636 = ATCC 14048 = DSM 759 Vibrio natriegens NBRC 15636 = ATCC 14048 = DSM 759 Vibrio natriegens NBRC 15636 = ATCC 14048 = DSM 759 | H3: 98.63 98.63 98.63 | I3: CP009977.1 CP016345.1 CP141822.1
A4: SA48 | B4: N | C4: 1463 | D4: Vibrio aestuarianus strain U29 Vibrio aestuarianus strain NBRC 15629 Vibrio aestuarianus strain 10_092 7MT1 | E4: 99.59 99.66 99.11 | F4: CP118709.1 NR_113780.1 CP091993.1 | G4: Vibrio aestuarianus strain NBRC 15629 Vibrio aestuarianus subsp. francensis strain 02/041 Vibrio aestuarianus strain OY 0-002 | H4: 99.66 98.83 99.36 | I4: NR_113780.1 NR_114937.1 NR_029254.1
A5: DSM507 | B5: N | C5: 1505 | D5: Aliivibrio fischeri isolate 61f92ba31ffaf1e247a49d66 Aliivibrio fischeri ATCC 7744 = JCM 18803 = DSM 507 Vibrio fischeri strain ET101 | E5: 99.73 99.73 99.73 | F5: OZ183479.1 CP092712.1 AY292923.1 | G5: Aliivibrio fischeri ATCC 7744 = JCM 18803 = DSM 507 Aliivibrio fischeri ATCC 7744 = JCM 18803 = DSM 507 Vibrio crassostreae LMG 22240 | H5: 99.73 99.73 99.60 | I5: CP092712.1 CP092713.1 AP025477.1
A6: Hal054 | B6: Y | C6: 1492 | D6: Vibrio diazotrophicus strain Hal053 Vibrio diazotrophicus strain ATCC 33466 Vibrio diazotrophicus strain Hal026 | E6: 100 99.33 99.26 | F6: MT406434.1 CP151842.1 MT406407.1 | G6: Vibrio diazotrophicus strain ATCC 33466 Vibrio diazotrophicus strain NBRC 103148 Vibrio diazotrophicus strain NS 16S | H6: 99.33 99.25 99.18 | I6: CP151842.1 NR_114217.1 NR_026123.1
A7: Hal281 | B7: N | C7: 1517 | D7: Vibrio cyclitrophicus strain Hal281 Vibrio cyclitrophicus strain JM-2012 Vibrio cyclitrophicus strain ED653 | E7: 100 99.80 99.67 | F7: MT406665.1 KF488567.1 CP065207.1 | G7: Vibrio cyclitrophicus LMG 21359 Vibrio cyclitrophicus LMG 21359 Vibrio echinoideorum DSM 107264 | H7: 99.74 99.74 99.54 | I7: AP025480.1 AP025481.1 AP025483.1
A8: PP-XX7 | B8: Y | C8: 1505 | D8: Vibrio sp. NBRC 101805 Vibrio metschnikovii 16S Vibrio metschnikovii strain 19CA03SA01 | E8: 98.57 96.94 96.87 | F8: AB681563.1 AY837747.1 CP101482.1 | G8: Vibrio viridaestus strain LJC006 Vibrio sp. LJC006 Vibrio diazotrophicus strain ATCC 33466 | H8: 96.54 96.54 96.34 | I8: NR_179904.1 MG745796.1 CP151842.1
A9: DSM24595 | B9: Y | C9: 1518 | D9: Vibrio alfacsensis strain VA-1 Vibrio alfacsensis 04Ya249 Vibrio alfacsensis 04Ya249 | E9: 99.80 99.80 99.80 | F9: CP140102.1 AP019850.1 AP019849.1 | G9: Vibrio alfacsensis strain CAIM 1831 Vibrio alfacsensis strain CAIM 1831 Vibrio ponticus 16S rRNA gene, type strain CECT 5869T | H9: 99.87 99.08 98.15 | I9: NR_118129.1 CP032093.1 AJ630103.1

Sheet percentage_phagocytosis
A1: sample_id | B1: vibrio_strain | C1: ankyrin_present | D1: self_vs_foreign | E1: time_min | F1: unstained_in_gate | G1: autoflourescence_DAPIadjusted | H1: rep_1_DAPI | I1: rep_1_perc_phagocytosis | J1: rep_2_DAPI | K1: rep_2_perc_phagocytosis | L1: rep_3_DAPI | M1: rep_3_perc_phagocytosis | N1: rep_4_DAPI | O1: rep_4_perc_phagocytosis | P1: rep_5_DAPI | Q1: rep_5_perc_phagocytosis | R1: DAPI_avg | S1: phago_avg_total | T1: phago_avg_DAPI_adjusted
A2: Hal281-30-1 | B2: Hal281 | C2: negative | D2: self | E2: 30 | F2: 0 | G2: 0.49 | H2: 37.06 | I2: 1.88 | J2: 37.12 | K2: 1.75 | L2: 36.43 | M2: 1.72 | N2: 37.31 | O2: 1.77 | P2: 37.65 | Q2: 1.82 | R2: =AVERAGE(H2,J2,L2,N2,P2) -> 37.114 | S2: =AVERAGE(I2,K2,M2,O2,Q2) -> 1.788 | T2: =(S2/R2*100)-G2 -> 4.327589
A3: Hal281-30-2 | B3: Hal281 | C3: negative | D3: self | E3: 30 | F3: 0 | G3: 0.49 | H3: 35.36 | I3: 0.59 | J3: 35.61 | K3: 0.54 | L3: 35.51 | M3: 0.56 | N3: 35.66 | O3: 0.54 | P3: 35.22 | Q3: 0.53 | R3: =AVERAGE(H3,J3,L3,N3,P3) -> 35.472 | S3: =AVERAGE(I3,K3,M3,O3,Q3) -> 0.552 | T3: =(S3/R3*100)-G3 -> 1.066157
A4: Hal281-30-3 | B4: Hal281 | C4: negative | D4: self | E4: 30 | F4: 0 | G4: 0.49 | H4: 34.97 | I4: 1.94 | J4: 35.21 | K4: 1.83 | L4: 35.4 | M4: 1.83 | N4: 35.41 | O4: 1.83 | P4: 35.97 | Q4: 1.87 | R4: =AVERAGE(H4,J4,L4,N4,P4) -> 35.392 | S4: =AVERAGE(I4,K4,M4,O4,Q4) -> 1.86 | T4: =(S4/R4*100)-G4 -> 4.765425
A5: Hal281-30-4 | B5: Hal281 | C5: negative | D5: self | E5: 30 | F5: 0 | G5: 0.49 | H5: 22.5 | I5: 1.05 | J5: 21.38 | K5: 0.81 | L5: 21.43 | M5: 0.81 | N5: 21.55 | O5: 0.82 | P5: 21.71 | Q5: 0.81 | R5: =AVERAGE(H5,J5,L5,N5,P5) -> 21.714 | S5: =AVERAGE(I5,K5,M5,O5,Q5) -> 0.86 | T5: =(S5/R5*100)-G5 -> 3.4705784
A6: Hal281-30-5 | B6: Hal281 | C6: negative | D6: self | E6: 30 | F6: 0 | G6: 0.49 | H6: 39.85 | I6: 1.69 | J6: 37.63 | K6: 1.5 | L6: 37.45 | M6: 1.5 | N6: 37.07 | O6: 1.47 | P6: 37.53 | Q6: 1.47 | R6: =AVERAGE(H6,J6,L6,N6,P6) -> 37.906 | S6: =AVERAGE(I6,K6,M6,O6,Q6) -> 1.526 | T6: =(S6/R6*100)-G6 -> 3.5357479
A7: Hal281-30-6 | B7: Hal281 | C7: negative | D7: self | E7: 30 | F7: 0 | G7: 0.49 | H7: 31.12 | I7: 1.11 | J7: 29.9 | K7: 0.98 | L7: 29.82 | M7: 0.94 | N7: 29.48 | O7: 0.96 | P7: 29.42 | Q7: 0.95 | R7: =AVERAGE(H7,J7,L7,N7,P7) -> 29.948 | S7: =AVERAGE(I7,K7,M7,O7,Q7) -> 0.988 | T7: =(S7/R7*100)-G7 -> 2.8090517
A8: Hal281-60-1 | B8: Hal281 | C8: negative | D8: self | E8: 60 | F8: 0 | G8: 0.49 | H8: 38.65 | I8: 2.45 | J8: 37.61 | K8: 2.19 | L8: 38.7 | M8: 2.22 | N8: 38.16 | O8: 2.17 | P8: 38.62 | Q8: 2.21 | R8: =AVERAGE(H8,J8,L8,N8,P8) -> 38.348 | S8: =AVERAGE(I8,K8,M8,O8,Q8) -> 2.248 | T8: =(S8/R8*100)-G8 -> 5.3721049
A9: Hal281-60-2 | B9: Hal281 | C9: negative | D9: self | E9: 60 | F9: 0 | G9: 0.49 | H9: 30.87 | I9: 3.47 | J9: 30.07 | K9: 3.26 | L9: 29.68 | M9: 3.14 | N9: 29.73 | O9: 3.23 | P9: 29.76 | Q9: 3.18 | R9: =AVERAGE(H9,J9,L9,N9,P9) -> 30.022 | S9: =AVERAGE(I9,K9,M9,O9,Q9) -> 3.256 | T9: =(S9/R9*100)-G9 -> 10.35538
A10: Hal281-60-3 | B10: Hal281 | C10: negative | D10: self | E10: 60 | F10: 0 | G10: 0.49 | H10: 36.72 | I10: 1.15 | J10: 35.92 | K10: 1.07 | L10: 36.03 | M10: 1.04 | N10: 36.17 | O10: 1.04 | P10: 36.26 | Q10: 1.04 | R10: =AVERAGE(H10,J10,L10,N10,P10) -> 36.22 | S10: =AVERAGE(I10,K10,M10,O10,Q10) -> 1.068 | T10: =(S10/R10*100)-G10 -> 2.4586472
A11: Hal281-60-4 | B11: Hal281 | C11: negative | D11: self | E11: 60 | F11: 0 | G11: 0.49 | H11: 22.84 | I11: 1.78 | J11: 21.7 | K11: 1.47 | L11: 21.19 | M11: 1.47 | N11: 21.47 | O11: 1.46 | P11: 21.68 | Q11: 1.49 | R11: =AVERAGE(H11,J11,L11,N11,P11) -> 21.776 | S11: =AVERAGE(I11,K11,M11,O11,Q11) -> 1.534 | T11: =(S11/R11*100)-G11 -> 6.5544526
A12: Hal281-60-5 | B12: Hal281 | C12: negative | D12: self | E12: 60 | F12: 0 | G12: 0.49 | H12: 31.18 | I12: 2.62 | J12: 29.15 | K12: 2.32 | L12: 29.36 | M12: 2.38 | N12: 29.22 | O12: 2.38 | P12: 29.45 | Q12: 2.39 | R12: =AVERAGE(H12,J12,L12,N12,P12) -> 29.672 | S12: =AVERAGE(I12,K12,M12,O12,Q12) -> 2.418 | T12: =(S12/R12*100)-G12 -> 7.6590968
A13: Hal281-60-6 | B13: Hal281 | C13: negative | D13: self | E13: 60 | F13: 0 | G13: 0.49 | H13: 36.98 | I13: 2.49 | J13: 34.07 | K13: 2.11 | L13: 34.86 | M13: 2.09 | N13: 34.85 | O13: 2.07 | P13: 34.14 | Q13: 2.06 | R13: =AVERAGE(H13,J13,L13,N13,P13) -> 34.98 | S13: =AVERAGE(I13,K13,M13,O13,Q13) -> 2.164 | T13: =(S13/R13*100)-G13 -> 5.6963922
A14: Hal054-30-1 | B14: Hal054 | C14: positive | D14: self | E14: 30 | F14: 0 | G14: 0.49 | H14: 25.21 | I14: 2.06 | J14: 24.31 | K14: 1.88 | L14: 24.29 | M14: 1.88 | N14: 24.27 | O14: 1.88 | P14: 24.24 | Q14: 1.86 | R14: =AVERAGE(H14,J14,L14,N14,P14) -> 24.464 | S14: =AVERAGE(I14,K14,M14,O14,Q14) -> 1.912 | T14: =(S14/R14*100)-G14 -> 7.3255657
A15: Hal054-30-2 | B15: Hal054 | C15: positive | D15: self | E15: 30 | F15: 0 | G15: 0.49 | H15: 5.64 | I15: 0.32 | J15: 5.69 | K15: 0.32 | L15: NA | M15: NA | N15: NA | O15: NA | P15: NA | Q15: NA | R15: =AVERAGE(H15,J15,L15,N15,P15) -> 5.665 | S15: =AVERAGE(I15,K15,M15,O15,Q15) -> 0.32 | T15: =(S15/R15*100)-G15 -> 5.1587202
A16: Hal054-30-3 | B16: Hal054 | C16: positive | D16: self | E16: 30 | F16: 0 | G16: 0.49 | H16: 25.62 | I16: 0.89 | J16: 26.87 | K16: 0.9 | L16: 25.48 | M16: 0.86 | N16: 25.14 | O16: 0.84 | P16: 25.06 | Q16: 0.84 | R16: =AVERAGE(H16,J16,L16,N16,P16) -> 25.634 | S16: =AVERAGE(I16,K16,M16,O16,Q16) -> 0.866 | T16: =(S16/R16*100)-G16 -> 2.8883257
A17: Hal054-60-1 | B17: Hal054 | C17: positive | D17: self | E17: 60 | F17: 0 | G17: 0.49 | H17: 20.07 | I17: 2.27 | J17: 20.37 | K17: 2.24 | L17: 20.45 | M17: 2.3 | N17: 20.27 | O17: 2.21 | P17: 20.61 | Q17: 2.28 | R17: =AVERAGE(H17,J17,L17,N17,P17) -> 20.354 | S17: =AVERAGE(I17,K17,M17,O17,Q17) -> 2.26 | T17: =(S17/R17*100)-G17 -> 10.613469
A18: Hal054-60-2 | B18: Hal054 | C18: positive | D18: self | E18: 60 | F18: 0 | G18: 0.49 | H18: 11.55 | I18: 2.04 | J18: 10.86 | K18: 1.94 | L18: NA | M18: NA | N18: NA | O18: NA | P18: NA | Q18: NA | R18: =AVERAGE(H18,J18,L18,N18,P18) -> 11.205 | S18: =AVERAGE(I18,K18,M18,O18,Q18) -> 1.99 | T18: =(S18/R18*100)-G18 -> 17.269929
A19: Hal054-60-3 | B19: Hal054 | C19: positive | D19: self | E19: 60 | F19: 0 | G19: 0.49 | H19: 16.63 | I19: 1.14 | J19: 16.53 | K19: 1.1 | L19: 16.66 | M19: 1.1 | N19: 16.81 | O19: 1.12 | P19: 16.59 | Q19: 1.09 | R19: =AVERAGE(H19,J19,L19,N19,P19) -> 16.644 | S19: =AVERAGE(I19,K19,M19,O19,Q19) -> 1.11 | T19: =(S19/R19*100)-G19 -> 6.1790699
A20: M60_M31-30-1 | B20: M60_M31 | C20: negative | D20: foreign | E20: 30 | F20: 0 | G20: 0.49 | H20: 35.52 | I20: 1.48 | J20: 35.7 | K20: 1.5 | L20: 35.69 | M20: 1.48 | N20: 34.55 | O20: 1.46 | P20: 27.64 | Q20: 1.19 | R20: =AVERAGE(H20,J20,L20,N20,P20) -> 33.82 | S20: =AVERAGE(I20,K20,M20,O20,Q20) -> 1.422 | T20: =(S20/R20*100)-G20 -> 3.7146127
A21: M60_M31-30-2 | B21: M60_M31 | C21: negative | D21: foreign | E21: 30 | F21: 0 | G21: 0.49 | H21: 16.07 | I21: 0.76 | J21: 15.61 | K21: 0.71 | L21: 15.03 | M21: 0.67 | N21: 14.92 | O21: 0.67 | P21: 14.6 | Q21: 0.66 | R21: =AVERAGE(H21,J21,L21,N21,P21) -> 15.246 | S21: =AVERAGE(I21,K21,M21,O21,Q21) -> 0.694 | T21: =(S21/R21*100)-G21 -> 4.0620136
A22: M60_M31-30-3 | B22: M60_M31 | C22: negative | D22: foreign | E22: 30 | F22: 0 | G22: 0.49 | H22: 14.29 | I22: 0.65 | J22: 14.16 | K22: 0.63 | L22: 14.07 | M22: 0.63 | N22: 14.21 | O22: 0.64 | P22: 14.11 | Q22: 0.63 | R22: =AVERAGE(H22,J22,L22,N22,P22) -> 14.168 | S22: =AVERAGE(I22,K22,M22,O22,Q22) -> 0.636 | T22: =(S22/R22*100)-G22 -> 3.9989893
A23: M60_M31-60-1 | B23: M60_M31 | C23: negative | D23: foreign | E23: 60 | F23: 0 | G23: 0.49 | H23: 18.9 | I23: 1.3 | J23: 18.55 | K23: 1.27 | L23: 18.55 | M23: 1.26 | N23: 18.62 | O23: 1.26 | P23: 18.81 | Q23: 1.32 | R23: =AVERAGE(H23,J23,L23,N23,P23) -> 18.686 | S23: =AVERAGE(I23,K23,M23,O23,Q23) -> 1.282 | T23: =(S23/R23*100)-G23 -> 6.3707514
A24: M60_M31-60-2 | B24: M60_M31 | C24: negative | D24: foreign | E24: 60 | F24: 0 | G24: 0.49 | H24: 6.61 | I24: 0.49 | J24: 6.49 | K24: 0.47 | L24: 6.45 | M24: 0.46 | N24: 6.32 | O24: 0.44 | P24: 6.44 | Q24: 0.45 | R24: =AVERAGE(H24,J24,L24,N24,P24) -> 6.462 | S24: =AVERAGE(I24,K24,M24,O24,Q24) -> 0.462 | T24: =(S24/R24*100)-G24 -> 6.6594893
A25: M60_M31-60-3 | B25: M60_M31 | C25: negative | D25: foreign | E25: 60 | F25: 0 | G25: 0.49 | H25: 26.77 | I25: 1.62 | J25: 25.89 | K25: 1.46 | L25: 25.55 | M25: 1.43 | N25: 25.51 | O25: 1.42 | P25: 25.64 | Q25: 1.44 | R25: =AVERAGE(H25,J25,L25,N25,P25) -> 25.872 | S25: =AVERAGE(I25,K25,M25,O25,Q25) -> 1.474 | T25: =(S25/R25*100)-G25 -> 5.2072789
A26: M60_M70-30-1 | B26: M60_M70 | C26: positive | D26: foreign | E26: 30 | F26: 0 | G26: 0.49 | H26: 22.8 | I26: 0.33 | J26: 22.72 | K26: 0.33 | L26: 22.94 | M26: 0.35 | N26: 22.87 | O26: 0.34 | P26: 22.8 | Q26: 0.33 | R26: =AVERAGE(H26,J26,L26,N26,P26) -> 22.826 | S26: =AVERAGE(I26,K26,M26,O26,Q26) -> 0.336 | T26: =(S26/R26*100)-G26 -> 0.98200561
A27: M60_M70-30-2 | B27: M60_M70 | C27: positive | D27: foreign | E27: 30 | F27: 0 | G27: 0.49 | H27: 12.8 | I27: 0.35 | J27: 12.76 | K27: 0.32 | L27: 12.43 | M27: 0.31 | N27: 12.58 | O27: 0.32 | P27: 12.56 | Q27: 0.33 | R27: =AVERAGE(H27,J27,L27,N27,P27) -> 12.626 | S27: =AVERAGE(I27,K27,M27,O27,Q27) -> 0.326 | T27: =(S27/R27*100)-G27 -> 2.0919737
A28: M60_M70-30-3 | B28: M60_M70 | C28: positive | D28: foreign | E28: 30 | F28: 0 | G28: 0.49 | H28: 13.53 | I28: 0.15 | J28: 12.78 | K28: 0.12 | L28: 12.95 | M28: 0.12 | N28: 13.01 | O28: 0.13 | P28: 12.99 | Q28: 0.13 | R28: =AVERAGE(H28,J28,L28,N28,P28) -> 13.052 | S28: =AVERAGE(I28,K28,M28,O28,Q28) -> 0.13 | T28: =(S28/R28*100)-G28 -> 0.50601594
A29: M60_M70-60-1 | B29: M60_M70 | C29: positive | D29: foreign | E29: 60 | F29: 0 | G29: 0.49 | H29: 25.37 | I29: 0.44 | J29: 24.43 | K29: 0.4 | L29: 24.5 | M29: 0.39 | N29: 24.74 | O29: 0.4 | P29: 24.65 | Q29: 0.38 | R29: =AVERAGE(H29,J29,L29,N29,P29) -> 24.738 | S29: =AVERAGE(I29,K29,M29,O29,Q29) -> 0.402 | T29: =(S29/R29*100)-G29 -> 1.1350303
A30: M60_M70-60-2 | B30: M60_M70 | C30: positive | D30: foreign | E30: 60 | F30: 0 | G30: 0.49 | H30: 5.01 | I30: 0.14 | J30: 4.81 | K30: 0.12 | L30: 4.95 | M30: 0.13 | N30: 4.88 | O30: 0.13 | P30: 4.66 | Q30: 0.13 | R30: =AVERAGE(H30,J30,L30,N30,P30) -> 4.862 | S30: =AVERAGE(I30,K30,M30,O30,Q30) -> 0.13 | T30: =(S30/R30*100)-G30 -> 2.1837968
A31: M60_M70-60-3 | B31: M60_M70 | C31: positive | D31: foreign | E31: 60 | F31: 0 | G31: 0.49 | H31: 4.42 | I31: 0.06 | J31: 4.38 | K31: 0.06 | L31: 4.41 | M31: 0.05 | N31: NA | O31: NA | P31: NA | Q31: NA | R31: =AVERAGE(H31,J31,L31,N31,P31) -> 4.4033333 | S31: =AVERAGE(I31,K31,M31,O31,Q31) -> 0.056666667 | T31: =(S31/R31*100)-G31 -> 0.79690386
A32: SA48-30-1 | B32: SA48 | C32: negative | D32: foreign | E32: 30 | F32: 0 | G32: 0.49 | H32: 37.82 | I32: 2.1 | J32: 36.67 | K32: 1.93 | L32: 37.24 | M32: 1.98 | N32: 36.98 | O32: 1.91 | P32: 37.04 | Q32: 1.94 | R32: =AVERAGE(H32,J32,L32,N32,P32) -> 37.15 | S32: =AVERAGE(I32,K32,M32,O32,Q32) -> 1.972 | T32: =(S32/R32*100)-G32 -> 4.81821
A33: SA48-30-2 | B33: SA48 | C33: negative | D33: foreign | E33: 30 | F33: 0 | G33: 0.49 | H33: 27.9 | I33: 1.39 | J33: 27.24 | K33: 1.28 | L33: 26.75 | M33: 1.27 | N33: 27.5 | O33: 1.31 | P33: 27.68 | Q33: 1.34 | R33: =AVERAGE(H33,J33,L33,N33,P33) -> 27.414 | S33: =AVERAGE(I33,K33,M33,O33,Q33) -> 1.318 | T33: =(S33/R33*100)-G33 -> 4.3177625
A34: SA48-30-3 | B34: SA48 | C34: negative | D34: foreign | E34: 30 | F34: 0 | G34: 0.49 | H34: 32.68 | I34: 3.1 | J34: 31.45 | K34: 2.9 | L34: 31.18 | M34: 2.85 | N34: 31.49 | O34: 2.92 | P34: 31.56 | Q34: 2.9 | R34: =AVERAGE(H34,J34,L34,N34,P34) -> 31.672 | S34: =AVERAGE(I34,K34,M34,O34,Q34) -> 2.934 | T34: =(S34/R34*100)-G34 -> 8.773703
A35: SA48-60-1 | B35: SA48 | C35: negative | D35: foreign | E35: 60 | F35: 0 | G35: 0.49 | H35: 31.8 | I35: 1.64 | J35: 31.04 | K35: 1.56 | L35: 30.89 | M35: 1.58 | N35: 30.87 | O35: 1.51 | P35: 31.17 | Q35: 1.59 | R35: =AVERAGE(H35,J35,L35,N35,P35) -> 31.154 | S35: =AVERAGE(I35,K35,M35,O35,Q35) -> 1.576 | T35: =(S35/R35*100)-G35 -> 4.5687405
A36: SA48-60-2 | B36: SA48 | C36: negative | D36: foreign | E36: 60 | F36: 0 | G36: 0.49 | H36: 19.86 | I36: 0.63 | J36: 19.07 | K36: 0.55 | L36: 18.49 | M36: 0.52 | N36: 18.31 | O36: 0.5 | P36: 18.72 | Q36: 0.53 | R36: =AVERAGE(H36,J36,L36,N36,P36) -> 18.89 | S36: =AVERAGE(I36,K36,M36,O36,Q36) -> 0.546 | T36: =(S36/R36*100)-G36 -> 2.4004182
A37: SA48-60-3 | B37: SA48 | C37: negative | D37: foreign | E37: 60 | F37: 0 | G37: 0.49 | H37: 17.59 | I37: 0.26 | J37: 15.25 | K37: 0.22 | L37: 15.12 | M37: 0.21 | N37: 14.87 | O37: 0.22 | P37: NA | Q37: NA | R37: =AVERAGE(H37,J37,L37,N37,P37) -> 15.7075 | S37: =AVERAGE(I37,K37,M37,O37,Q37) -> 0.2275 | T37: =(S37/R37*100)-G37 -> 0.9583527
A38: DMZ507-30-1 | B38: DMZ507 | C38: negative | D38: foreign | E38: 30 | F38: 0 | G38: 0.49 | H38: 29.75 | I38: 1.99 | J38: 28.98 | K38: 1.86 | L38: 29.21 | M38: 1.88 | N38: 29.3 | O38: 1.9 | P38: 29.37 | Q38: 1.9 | R38: =AVERAGE(H38,J38,L38,N38,P38) -> 29.322 | S38: =AVERAGE(I38,K38,M38,O38,Q38) -> 1.906 | T38: =(S38/R38*100)-G38 -> 6.0102387
A39: DMZ507-30-2 | B39: DMZ507 | C39: negative | D39: foreign | E39: 30 | F39: 0 | G39: 0.49 | H39: 11.05 | I39: 0.35 | J39: 10.7 | K39: 0.33 | L39: 10.55 | M39: 0.32 | N39: 10.42 | O39: 0.33 | P39: 10.05 | Q39: 0.3 | R39: =AVERAGE(H39,J39,L39,N39,P39) -> 10.554 | S39: =AVERAGE(I39,K39,M39,O39,Q39) -> 0.326 | T39: =(S39/R39*100)-G39 -> 2.5988763
A40: DMZ507-60-1 | B40: DMZ507 | C40: negative | D40: foreign | E40: 60 | F40: 0 | G40: 0.49 | H40: 23.8 | I40: 2.84 | J40: 24.02 | K40: 2.72 | L40: 23.59 | M40: 2.69 | N40: 23.53 | O40: 2.67 | P40: 23.68 | Q40: 2.7 | R40: =AVERAGE(H40,J40,L40,N40,P40) -> 23.724 | S40: =AVERAGE(I40,K40,M40,O40,Q40) -> 2.724 | T40: =(S40/R40*100)-G40 -> 10.992044
...

Sheet percentage_phagocytosis_R
A1: sample_id | B1: vibrio_strain | C1: ankyrin_present | D1: self_vs_foreign | E1: time_min | F1: unstained_in_gate | G1: autoflourescence_DAPIadjusted | H1: rep_1_DAPI | I1: rep_1_perc_phagocytosis | J1: rep_2_DAPI | K1: rep_2_perc_phagocytosis | L1: rep_3_DAPI | M1: rep_3_perc_phagocytosis | N1: rep_4_DAPI | O1: rep_4_perc_phagocytosis | P1: rep_5_DAPI | Q1: rep_5_perc_phagocytosis | R1: DAPI_avg | S1: phago_avg_total | T1: phago_avg_DAPI_adjusted | U1: background | V1: t0_vibrio
A2: Hal281-30-1 | B2: Hal281 | C2: negative | D2: self | E2: 30 | F2: 0 | G2: 0.49 | H2: 37.06 | I2: 1.88 | J2: 37.12 | K2: 1.75 | L2: 36.43 | M2: 1.72 | N2: 37.31 | O2: 1.77 | P2: 37.65 | Q2: 1.82 | R2: =AVERAGE(H2,J2,L2,N2,P2) -> 37.114 | S2: =AVERAGE(I2,K2,M2,O2,Q2) -> 1.788 | T2: =(S2/R2*100)-G2 -> 4.327589 | U2: NA | V2: NA
A3: Hal281-30-2 | B3: Hal281 | C3: negative | D3: self | E3: 30 | F3: 0 | G3: 0.49 | H3: 35.36 | I3: 0.59 | J3: 35.61 | K3: 0.54 | L3: 35.51 | M3: 0.56 | N3: 35.66 | O3: 0.54 | P3: 35.22 | Q3: 0.53 | R3: =AVERAGE(H3,J3,L3,N3,P3) -> 35.472 | S3: =AVERAGE(I3,K3,M3,O3,Q3) -> 0.552 | T3: =(S3/R3*100)-G3 -> 1.066157 | U3: NA | V3: NA
A4: Hal281-30-3 | B4: Hal281 | C4: negative | D4: self | E4: 30 | F4: 0 | G4: 0.49 | H4: 34.97 | I4: 1.94 | J4: 35.21 | K4: 1.83 | L4: 35.4 | M4: 1.83 | N4: 35.41 | O4: 1.83 | P4: 35.97 | Q4: 1.87 | R4: =AVERAGE(H4,J4,L4,N4,P4) -> 35.392 | S4: =AVERAGE(I4,K4,M4,O4,Q4) -> 1.86 | T4: =(S4/R4*100)-G4 -> 4.765425 | U4: NA | V4: NA
A5: Hal281-30-4 | B5: Hal281 | C5: negative | D5: self | E5: 30 | F5: 0 | G5: 0.49 | H5: 22.5 | I5: 1.05 | J5: 21.38 | K5: 0.81 | L5: 21.43 | M5: 0.81 | N5: 21.55 | O5: 0.82 | P5: 21.71 | Q5: 0.81 | R5: =AVERAGE(H5,J5,L5,N5,P5) -> 21.714 | S5: =AVERAGE(I5,K5,M5,O5,Q5) -> 0.86 | T5: =(S5/R5*100)-G5 -> 3.4705784 | U5: =AVERAGE(uptake_rates_raw!W2:W7) -> 324802.4 | V5: 1017952
A6: Hal281-30-5 | B6: Hal281 | C6: negative | D6: self | E6: 30 | F6: 0 | G6: 0.49 | H6: 39.85 | I6: 1.69 | J6: 37.63 | K6: 1.5 | L6: 37.45 | M6: 1.5 | N6: 37.07 | O6: 1.47 | P6: 37.53 | Q6: 1.47 | R6: =AVERAGE(H6,J6,L6,N6,P6) -> 37.906 | S6: =AVERAGE(I6,K6,M6,O6,Q6) -> 1.526 | T6: =(S6/R6*100)-G6 -> 3.5357479 | U6: =AVERAGE(uptake_rates_raw!W8:W13) -> 323553.89 | V6: 1021451
A7: Hal281-30-6 | B7: Hal281 | C7: negative | D7: self | E7: 30 | F7: 0 | G7: 0.49 | H7: 31.12 | I7: 1.11 | J7: 29.9 | K7: 0.98 | L7: 29.82 | M7: 0.94 | N7: 29.48 | O7: 0.96 | P7: 29.42 | Q7: 0.95 | R7: =AVERAGE(H7,J7,L7,N7,P7) -> 29.948 | S7: =AVERAGE(I7,K7,M7,O7,Q7) -> 0.988 | T7: =(S7/R7*100)-G7 -> 2.8090517 | U7: =AVERAGE(uptake_rates_raw!W14:W19) -> 286147.7 | V7: 1040133
A8: Hal281-60-1 | B8: Hal281 | C8: negative | D8: self | E8: 60 | F8: 0 | G8: 0.49 | H8: 38.65 | I8: 2.45 | J8: 37.61 | K8: 2.19 | L8: 38.7 | M8: 2.22 | N8: 38.16 | O8: 2.17 | P8: 38.62 | Q8: 2.21 | R8: =AVERAGE(H8,J8,L8,N8,P8) -> 38.348 | S8: =AVERAGE(I8,K8,M8,O8,Q8) -> 2.248 | T8: =(S8/R8*100)-G8 -> 5.3721049 | U8: NA | V8: NA
A9: Hal281-60-2 | B9: Hal281 | C9: negative | D9: self | E9: 60 | F9: 0 | G9: 0.49 | H9: 30.87 | I9: 3.47 | J9: 30.07 | K9: 3.26 | L9: 29.68 | M9: 3.14 | N9: 29.73 | O9: 3.23 | P9: 29.76 | Q9: 3.18 | R9: =AVERAGE(H9,J9,L9,N9,P9) -> 30.022 | S9: =AVERAGE(I9,K9,M9,O9,Q9) -> 3.256 | T9: =(S9/R9*100)-G9 -> 10.35538 | U9: NA | V9: NA
A10: Hal281-60-3 | B10: Hal281 | C10: negative | D10: self | E10: 60 | F10: 0 | G10: 0.49 | H10: 36.72 | I10: 1.15 | J10: 35.92 | K10: 1.07 | L10: 36.03 | M10: 1.04 | N10: 36.17 | O10: 1.04 | P10: 36.26 | Q10: 1.04 | R10: =AVERAGE(H10,J10,L10,N10,P10) -> 36.22 | S10: =AVERAGE(I10,K10,M10,O10,Q10) -> 1.068 | T10: =(S10/R10*100)-G10 -> 2.4586472 | U10: NA | V10: NA
A11: Hal281-60-4 | B11: Hal281 | C11: negative | D11: self | E11: 60 | F11: 0 | G11: 0.49 | H11: 22.84 | I11: 1.78 | J11: 21.7 | K11: 1.47 | L11: 21.19 | M11: 1.47 | N11: 21.47 | O11: 1.46 | P11: 21.68 | Q11: 1.49 | R11: =AVERAGE(H11,J11,L11,N11,P11) -> 21.776 | S11: =AVERAGE(I11,K11,M11,O11,Q11) -> 1.534 | T11: =(S11/R11*100)-G11 -> 6.5544526 | U11: =AVERAGE(uptake_rates_raw!W20:W27) -> 298416.21 | V11: 1058131
A12: Hal281-60-5 | B12: Hal281 | C12: negative | D12: self | E12: 60 | F12: 0 | G12: 0.49 | H12: 31.18 | I12: 2.62 | J12: 29.15 | K12: 2.32 | L12: 29.36 | M12: 2.38 | N12: 29.22 | O12: 2.38 | P12: 29.45 | Q12: 2.39 | R12: =AVERAGE(H12,J12,L12,N12,P12) -> 29.672 | S12: =AVERAGE(I12,K12,M12,O12,Q12) -> 2.418 | T12: =(S12/R12*100)-G12 -> 7.6590968 | U12: =AVERAGE(uptake_rates_raw!W28:W35) -> 265886.53 | V12: 1314042
A13: Hal281-60-6 | B13: Hal281 | C13: negative | D13: self | E13: 60 | F13: 0 | G13: 0.49 | H13: 36.98 | I13: 2.49 | J13: 34.07 | K13: 2.11 | L13: 34.86 | M13: 2.09 | N13: 34.85 | O13: 2.07 | P13: 34.14 | Q13: 2.06 | R13: =AVERAGE(H13,J13,L13,N13,P13) -> 34.98 | S13: =AVERAGE(I13,K13,M13,O13,Q13) -> 2.164 | T13: =(S13/R13*100)-G13 -> 5.6963922 | U13: =AVERAGE(uptake_rates_raw!W36:W43) -> 263654.78 | V13: 1119560
A14: Hal054-30-1 | B14: Hal054 | C14: positive | D14: self | E14: 30 | F14: 0 | G14: 0.49 | H14: 25.21 | I14: 2.06 | J14: 24.31 | K14: 1.88 | L14: 24.29 | M14: 1.88 | N14: 24.27 | O14: 1.88 | P14: 24.24 | Q14: 1.86 | R14: =AVERAGE(H14,J14,L14,N14,P14) -> 24.464 | S14: =AVERAGE(I14,K14,M14,O14,Q14) -> 1.912 | T14: =(S14/R14*100)-G14 -> 7.3255657 | U14: =AVERAGE(uptake_rates_raw!W44:W49) -> 290977.05 | V14: 1557094
A15: Hal054-30-2 | B15: Hal054 | C15: positive | D15: self | E15: 30 | F15: 0 | G15: 0.49 | H15: 5.64 | I15: 0.32 | J15: 5.69 | K15: 0.32 | L15: NA | M15: NA | N15: NA | O15: NA | P15: NA | Q15: NA | R15: =AVERAGE(H15,J15,L15,N15,P15) -> 5.665 | S15: =AVERAGE(I15,K15,M15,O15,Q15) -> 0.32 | T15: =(S15/R15*100)-G15 -> 5.1587202 | U15: =AVERAGE(uptake_rates_raw!W50:W55) -> 257314.37 | V15: 1955639
A16: Hal054-30-3 | B16: Hal054 | C16: positive | D16: self | E16: 30 | F16: 0 | G16: 0.49 | H16: 25.62 | I16: 0.89 | J16: 26.87 | K16: 0.9 | L16: 25.48 | M16: 0.86 | N16: 25.14 | O16: 0.84 | P16: 25.06 | Q16: 0.84 | R16: =AVERAGE(H16,J16,L16,N16,P16) -> 25.634 | S16: =AVERAGE(I16,K16,M16,O16,Q16) -> 0.866 | T16: =(S16/R16*100)-G16 -> 2.8883257 | U16: =AVERAGE(uptake_rates_raw!W56:W61) -> 287502 | V16: 2241211
A17: Hal054-60-1 | B17: Hal054 | C17: positive | D17: self | E17: 60 | F17: 0 | G17: 0.49 | H17: 20.07 | I17: 2.27 | J17: 20.37 | K17: 2.24 | L17: 20.45 | M17: 2.3 | N17: 20.27 | O17: 2.21 | P17: 20.61 | Q17: 2.28 | R17: =AVERAGE(H17,J17,L17,N17,P17) -> 20.354 | S17: =AVERAGE(I17,K17,M17,O17,Q17) -> 2.26 | T17: =(S17/R17*100)-G17 -> 10.613469 | U17: =AVERAGE(uptake_rates_raw!W62:W69) -> 272574.54 | V17: 2179579
A18: Hal054-60-2 | B18: Hal054 | C18: positive | D18: self | E18: 60 | F18: 0 | G18: 0.49 | H18: 11.55 | I18: 2.04 | J18: 10.86 | K18: 1.94 | L18: NA | M18: NA | N18: NA | O18: NA | P18: NA | Q18: NA | R18: =AVERAGE(H18,J18,L18,N18,P18) -> 11.205 | S18: =AVERAGE(I18,K18,M18,O18,Q18) -> 1.99 | T18: =(S18/R18*100)-G18 -> 17.269929 | U18: =AVERAGE(uptake_rates_raw!W70:W77) -> 216228.07 | V18: 2163130
A19: Hal054-60-3 | B19: Hal054 | C19: positive | D19: self | E19: 60 | F19: 0 | G19: 0.49 | H19: 16.63 | I19: 1.14 | J19: 16.53 | K19: 1.1 | L19: 16.66 | M19: 1.1 | N19: 16.81 | O19: 1.12 | P19: 16.59 | Q19: 1.09 | R19: =AVERAGE(H19,J19,L19,N19,P19) -> 16.644 | S19: =AVERAGE(I19,K19,M19,O19,Q19) -> 1.11 | T19: =(S19/R19*100)-G19 -> 6.1790699 | U19: =AVERAGE(uptake_rates_raw!W78,uptake_rates_raw!W80:W85) -> 274154.5 | V19: 2317080
A20: M60_M31-30-1 | B20: M60_M31 | C20: negative | D20: foreign | E20: 30 | F20: 0 | G20: 0.49 | H20: 35.52 | I20: 1.48 | J20: 35.7 | K20: 1.5 | L20: 35.69 | M20: 1.48 | N20: 34.55 | O20: 1.46 | P20: 27.64 | Q20: 1.19 | R20: =AVERAGE(H20,J20,L20,N20,P20) -> 33.82 | S20: =AVERAGE(I20,K20,M20,O20,Q20) -> 1.422 | T20: =(S20/R20*100)-G20 -> 3.7146127 | U20: =AVERAGE(uptake_rates_raw!W128:W133) -> 17423.154 | V20: 985075
A21: M60_M31-30-2 | B21: M60_M31 | C21: negative | D21: foreign | E21: 30 | F21: 0 | G21: 0.49 | H21: 16.07 | I21: 0.76 | J21: 15.61 | K21: 0.71 | L21: 15.03 | M21: 0.67 | N21: 14.92 | O21: 0.67 | P21: 14.6 | Q21: 0.66 | R21: =AVERAGE(H21,J21,L21,N21,P21) -> 15.246 | S21: =AVERAGE(I21,K21,M21,O21,Q21) -> 0.694 | T21: =(S21/R21*100)-G21 -> 4.0620136 | U21: =AVERAGE(uptake_rates_raw!W134:W139) -> 16873.253 | V21: 993637
A22: M60_M31-30-3 | B22: M60_M31 | C22: negative | D22: foreign | E22: 30 | F22: 0 | G22: 0.49 | H22: 14.29 | I22: 0.65 | J22: 14.16 | K22: 0.63 | L22: 14.07 | M22: 0.63 | N22: 14.21 | O22: 0.64 | P22: 14.11 | Q22: 0.63 | R22: =AVERAGE(H22,J22,L22,N22,P22) -> 14.168 | S22: =AVERAGE(I22,K22,M22,O22,Q22) -> 0.636 | T22: =(S22/R22*100)-G22 -> 3.9989893 | U22: =AVERAGE(uptake_rates_raw!W140:W145) -> 17713.573 | V22: 1076705
A23: M60_M31-60-1 | B23: M60_M31 | C23: negative | D23: foreign | E23: 60 | F23: 0 | G23: 0.49 | H23: 18.9 | I23: 1.3 | J23: 18.55 | K23: 1.27 | L23: 18.55 | M23: 1.26 | N23: 18.62 | O23: 1.26 | P23: 18.81 | Q23: 1.32 | R23: =AVERAGE(H23,J23,L23,N23,P23) -> 18.686 | S23: =AVERAGE(I23,K23,M23,O23,Q23) -> 1.282 | T23: =(S23/R23*100)-G23 -> 6.3707514 | U23: =AVERAGE(uptake_rates_raw!W146:W153) -> 19322.722 | V23: 1147028
A24: M60_M31-60-2 | B24: M60_M31 | C24: negative | D24: foreign | E24: 60 | F24: 0 | G24: 0.49 | H24: 6.61 | I24: 0.49 | J24: 6.49 | K24: 0.47 | L24: 6.45 | M24: 0.46 | N24: 6.32 | O24: 0.44 | P24: 6.44 | Q24: 0.45 | R24: =AVERAGE(H24,J24,L24,N24,P24) -> 6.462 | S24: =AVERAGE(I24,K24,M24,O24,Q24) -> 0.462 | T24: =(S24/R24*100)-G24 -> 6.6594893 | U24: =AVERAGE(uptake_rates_raw!W154:W161) -> 24104.181 | V24: 1113526
A25: M60_M31-60-3 | B25: M60_M31 | C25: negative | D25: foreign | E25: 60 | F25: 0 | G25: 0.49 | H25: 26.77 | I25: 1.62 | J25: 25.89 | K25: 1.46 | L25: 25.55 | M25: 1.43 | N25: 25.51 | O25: 1.42 | P25: 25.64 | Q25: 1.44 | R25: =AVERAGE(H25,J25,L25,N25,P25) -> 25.872 | S25: =AVERAGE(I25,K25,M25,O25,Q25) -> 1.474 | T25: =(S25/R25*100)-G25 -> 5.2072789 | U25: =AVERAGE(uptake_rates_raw!W162:W169) -> 24399.927 | V25: 1150848
A26: M60_M70-30-1 | B26: M60_M70 | C26: positive | D26: foreign | E26: 30 | F26: 0 | G26: 0.49 | H26: 22.8 | I26: 0.33 | J26: 22.72 | K26: 0.33 | L26: 22.94 | M26: 0.35 | N26: 22.87 | O26: 0.34 | P26: 22.8 | Q26: 0.33 | R26: =AVERAGE(H26,J26,L26,N26,P26) -> 22.826 | S26: =AVERAGE(I26,K26,M26,O26,Q26) -> 0.336 | T26: =(S26/R26*100)-G26 -> 0.98200561 | U26: =AVERAGE(uptake_rates_raw!W170:W175) -> 281728.54 | V26: 1099312
A27: M60_M70-30-2 | B27: M60_M70 | C27: positive | D27: foreign | E27: 30 | F27: 0 | G27: 0.49 | H27: 12.8 | I27: 0.35 | J27: 12.76 | K27: 0.32 | L27: 12.43 | M27: 0.31 | N27: 12.58 | O27: 0.32 | P27: 12.56 | Q27: 0.33 | R27: =AVERAGE(H27,J27,L27,N27,P27) -> 12.626 | S27: =AVERAGE(I27,K27,M27,O27,Q27) -> 0.326 | T27: =(S27/R27*100)-G27 -> 2.0919737 | U27: =AVERAGE(uptake_rates_raw!W176:W181) -> 296543.91 | V27: 1054748
A28: M60_M70-30-3 | B28: M60_M70 | C28: positive | D28: foreign | E28: 30 | F28: 0 | G28: 0.49 | H28: 13.53 | I28: 0.15 | J28: 12.78 | K28: 0.12 | L28: 12.95 | M28: 0.12 | N28: 13.01 | O28: 0.13 | P28: 12.99 | Q28: 0.13 | R28: =AVERAGE(H28,J28,L28,N28,P28) -> 13.052 | S28: =AVERAGE(I28,K28,M28,O28,Q28) -> 0.13 | T28: =(S28/R28*100)-G28 -> 0.50601594 | U28: =AVERAGE(uptake_rates_raw!W182:W187) -> 413356.29 | V28: 1044290
A29: M60_M70-60-1 | B29: M60_M70 | C29: positive | D29: foreign | E29: 60 | F29: 0 | G29: 0.49 | H29: 25.37 | I29: 0.44 | J29: 24.43 | K29: 0.4 | L29: 24.5 | M29: 0.39 | N29: 24.74 | O29: 0.4 | P29: 24.65 | Q29: 0.38 | R29: =AVERAGE(H29,J29,L29,N29,P29) -> 24.738 | S29: =AVERAGE(I29,K29,M29,O29,Q29) -> 0.402 | T29: =(S29/R29*100)-G29 -> 1.1350303 | U29: =AVERAGE(uptake_rates_raw!W188:W195) -> 464982.89 | V29: 1085642
A30: M60_M70-60-2 | B30: M60_M70 | C30: positive | D30: foreign | E30: 60 | F30: 0 | G30: 0.49 | H30: 5.01 | I30: 0.14 | J30: 4.81 | K30: 0.12 | L30: 4.95 | M30: 0.13 | N30: 4.88 | O30: 0.13 | P30: 4.66 | Q30: 0.13 | R30: =AVERAGE(H30,J30,L30,N30,P30) -> 4.862 | S30: =AVERAGE(I30,K30,M30,O30,Q30) -> 0.13 | T30: =(S30/R30*100)-G30 -> 2.1837968 | U30: =AVERAGE(uptake_rates_raw!W196:W203) -> 356611.85 | V30: 805625
A31: M60_M70-60-3 | B31: M60_M70 | C31: positive | D31: foreign | E31: 60 | F31: 0 | G31: 0.49 | H31: 4.42 | I31: 0.06 | J31: 4.38 | K31: 0.06 | L31: 4.41 | M31: 0.05 | N31: NA | O31: NA | P31: NA | Q31: NA | R31: =AVERAGE(H31,J31,L31,N31,P31) -> 4.4033333 | S31: =AVERAGE(I31,K31,M31,O31,Q31) -> 0.056666667 | T31: =(S31/R31*100)-G31 -> 0.79690386 | U31: =AVERAGE(uptake_rates_raw!W204:W211) -> 359764.65 | V31: 911427
A32: SA48-30-1 | B32: SA48 | C32: negative | D32: foreign | E32: 30 | F32: 0 | G32: 0.49 | H32: 37.82 | I32: 2.1 | J32: 36.67 | K32: 1.93 | L32: 37.24 | M32: 1.98 | N32: 36.98 | O32: 1.91 | P32: 37.04 | Q32: 1.94 | R32: =AVERAGE(H32,J32,L32,N32,P32) -> 37.15 | S32: =AVERAGE(I32,K32,M32,O32,Q32) -> 1.972 | T32: =(S32/R32*100)-G32 -> 4.81821 | U32: =AVERAGE(uptake_rates_raw!W86:W87,uptake_rates_raw!W89:W91) -> 189271.86 | V32: 1049158
A33: SA48-30-2 | B33: SA48 | C33: negative | D33: foreign | E33: 30 | F33: 0 | G33: 0.49 | H33: 27.9 | I33: 1.39 | J33: 27.24 | K33: 1.28 | L33: 26.75 | M33: 1.27 | N33: 27.5 | O33: 1.31 | P33: 27.68 | Q33: 1.34 | R33: =AVERAGE(H33,J33,L33,N33,P33) -> 27.414 | S33: =AVERAGE(I33,K33,M33,O33,Q33) -> 1.318 | T33: =(S33/R33*100)-G33 -> 4.3177625 | U33: =AVERAGE(uptake_rates_raw!W92:W97) -> 197682.63 | V33: 1329509
A34: SA48-30-3 | B34: SA48 | C34: negative | D34: foreign | E34: 30 | F34: 0 | G34: 0.49 | H34: 32.68 | I34: 3.1 | J34: 31.45 | K34: 2.9 | L34: 31.18 | M34: 2.85 | N34: 31.49 | O34: 2.92 | P34: 31.56 | Q34: 2.9 | R34: =AVERAGE(H34,J34,L34,N34,P34) -> 31.672 | S34: =AVERAGE(I34,K34,M34,O34,Q34) -> 2.934 | T34: =(S34/R34*100)-G34 -> 8.773703 | U34: =AVERAGE(uptake_rates_raw!W98:W103) -> 205179.64 | V34: 1381605
A35: SA48-60-1 | B35: SA48 | C35: negative | D35: foreign | E35: 60 | F35: 0 | G35: 0.49 | H35: 31.8 | I35: 1.64 | J35: 31.04 | K35: 1.56 | L35: 30.89 | M35: 1.58 | N35: 30.87 | O35: 1.51 | P35: 31.17 | Q35: 1.59 | R35: =AVERAGE(H35,J35,L35,N35,P35) -> 31.154 | S35: =AVERAGE(I35,K35,M35,O35,Q35) -> 1.576 | T35: =(S35/R35*100)-G35 -> 4.5687405 | U35: =AVERAGE(uptake_rates_raw!W104:W111) -> 171410.56 | V35: 1355414
A36: SA48-60-2 | B36: SA48 | C36: negative | D36: foreign | E36: 60 | F36: 0 | G36: 0.49 | H36: 19.86 | I36: 0.63 | J36: 19.07 | K36: 0.55 | L36: 18.49 | M36: 0.52 | N36: 18.31 | O36: 0.5 | P36: 18.72 | Q36: 0.53 | R36: =AVERAGE(H36,J36,L36,N36,P36) -> 18.89 | S36: =AVERAGE(I36,K36,M36,O36,Q36) -> 0.546 | T36: =(S36/R36*100)-G36 -> 2.4004182 | U36: =AVERAGE(uptake_rates_raw!W112:W119) -> 153956.28 | V36: 1346229
A37: SA48-60-3 | B37: SA48 | C37: negative | D37: foreign | E37: 60 | F37: 0 | G37: 0.49 | H37: 17.59 | I37: 0.26 | J37: 15.25 | K37: 0.22 | L37: 15.12 | M37: 0.21 | N37: 14.87 | O37: 0.22 | P37: NA | Q37: NA | R37: =AVERAGE(H37,J37,L37,N37,P37) -> 15.7075 | S37: =AVERAGE(I37,K37,M37,O37,Q37) -> 0.2275 | T37: =(S37/R37*100)-G37 -> 0.9583527 | U37: =AVERAGE(uptake_rates_raw!W120:W127) -> 168240.66 | V37: 1364216
A38: DMZ507-30-1 | B38: DMZ507 | C38: negative | D38: foreign | E38: 30 | F38: 0 | G38: 0.49 | H38: 29.75 | I38: 1.99 | J38: 28.98 | K38: 1.86 | L38: 29.21 | M38: 1.88 | N38: 29.3 | O38: 1.9 | P38: 29.37 | Q38: 1.9 | R38: =AVERAGE(H38,J38,L38,N38,P38) -> 29.322 | S38: =AVERAGE(I38,K38,M38,O38,Q38) -> 1.906 | T38: =(S38/R38*100)-G38 -> 6.0102387 | U38: NA | V38: NA
A39: DMZ507-30-2 | B39: DMZ507 | C39: negative | D39: foreign | E39: 30 | F39: 0 | G39: 0.49 | H39: 11.05 | I39: 0.35 | J39: 10.7 | K39: 0.33 | L39: 10.55 | M39: 0.32 | N39: 10.42 | O39: 0.33 | P39: 10.05 | Q39: 0.3 | R39: =AVERAGE(H39,J39,L39,N39,P39) -> 10.554 | S39: =AVERAGE(I39,K39,M39,O39,Q39) -> 0.326 | T39: =(S39/R39*100)-G39 -> 2.5988763 | U39: NA | V39: NA
A40: DMZ507-60-1 | B40: DMZ507 | C40: negative | D40: foreign | E40: 60 | F40: 0 | G40: 0.49 | H40: 23.8 | I40: 2.84 | J40: 24.02 | K40: 2.72 | L40: 23.59 | M40: 2.69 | N40: 23.53 | O40: 2.67 | P40: 23.68 | Q40: 2.7 | R40: =AVERAGE(H40,J40,L40,N40,P40) -> 23.724 | S40: =AVERAGE(I40,K40,M40,O40,Q40) -> 2.724 | T40: =(S40/R40*100)-G40 -> 10.992044 | U40: NA | V40: NA
...

Sheet uptake_rates_raw
A1: sample_id | B1: vibrio_strain | C1: strain_replicate | D1: ankyrin_present | E1: self_vs_foreign | F1: sponge_weight_g | G1: time_min | H1: sample_volume_µL | I1: dilution | J1: bac_count1 | K1: bead_count1 | L1: bac_count2 | M1: bead_count2 | N1: bac_count3 | O1: bead_count3 | P1: bac_count4 | Q1: bead_count4 | R1: final_vibrio/mL | S1: norm_factor | T1: norm_vibrio/mL | U1: total_count | V1: unstained_count | W1: unstained_calc
A2: Hal281-30-4-w0 | B2: Hal281 | C2: Hal281-30-4 | D2: No | E2: self | F2: 4.701 | G2: 0 | H2: 1002 | I2: 6 | J2: 4063 | K2: 1159 | L2: 3614 | M2: 1065 | N2: 3888 | O2: 1116 | P2: 3472 | Q2: 1064 | R2: =AVERAGE(J2/K2,L2/M2,N2/O2,P2/Q2)*(48000/H2)*I2*1000 -> 980555.52 | S2: =1309300/R2 -> 1.3352635 | T2: =R2*S2 -> 1309300 | U2: 83930 | V2: 58070 | W2: =V2*I2/H2*1000 -> 347724.55
A3: Hal281-30-4-w2 | B3: Hal281 | C3: Hal281-30-4 | D3: No | E3: self | F3: 4.701 | G3: 2 | H3: 1002 | I3: 6 | J3: 3363 | K3: 1033 | L3: 3644 | M3: 1034 | N3: 3333 | O3: 1034 | P3: 3369 | Q3: 1055 | R3: =AVERAGE(J3/K3,L3/M3,N3/O3,P3/Q3)*(48000/H3)*I3*1000 -> 948252.46 | S3: 1.34 | T3: =R3*S3 -> 1270658.3 | U3: 72271 | V3: 48801 | W3: =V3*I3/H3*1000 -> 292221.56
A4: Hal281-30-4-w5 | B4: Hal281 | C4: Hal281-30-4 | D4: No | E4: self | F4: 4.701 | G4: 5 | H4: 1002 | I4: 6 | J4: 4389 | K4: 1066 | L4: 5138 | M4: 1227 | N4: 4116 | O4: 1021 | P4: 3927 | Q4: 1025 | R4: =AVERAGE(J4/K4,L4/M4,N4/O4,P4/Q4)*(48000/H4)*I4*1000 -> 1161720.1 | S4: 1.34 | T4: =R4*S4 -> 1556704.9 | U4: 92136 | V4: 64634 | W4: =V4*I4/H4*1000 -> 387029.94
A5: Hal281-30-4-w10 | B5: Hal281 | C5: Hal281-30-4 | D5: No | E5: self | F5: 4.701 | G5: 10 | H5: 1002 | I5: 6 | J5: 3001 | K5: 1051 | L5: 2978 | M5: 1032 | N5: 3102 | O5: 1037 | P5: 3087 | Q5: 1032 | R5: =AVERAGE(J5/K5,L5/M5,N5/O5,P5/Q5)*(48000/H5)*I5*1000 -> 842416.88 | S5: 1.34 | T5: =R5*S5 -> 1128838.6 | U5: 74853 | V5: 48181 | W5: =V5*I5/H5*1000 -> 288508.98
A6: Hal281-30-4-w15 | B6: Hal281 | C6: Hal281-30-4 | D6: No | E6: self | F6: 4.701 | G6: 15 | H6: 1002 | I6: 6 | J6: 3036 | K6: 1019 | L6: 3618 | M6: 1029 | N6: 3488 | O6: 1044 | P6: 3395 | Q6: 1022 | R6: =AVERAGE(J6/K6,L6/M6,N6/O6,P6/Q6)*(48000/H6)*I6*1000 -> 945509.5 | S6: 1.34 | T6: =R6*S6 -> 1266982.7 | U6: 73995 | V6: 52465 | W6: =V6*I6/H6*1000 -> 314161.68
A7: Hal281-30-4-w30 | B7: Hal281 | C7: Hal281-30-4 | D7: No | E7: self | F7: 4.701 | G7: 30 | H7: 1002 | I7: 6 | J7: 2914 | K7: 1039 | L7: 3011 | M7: 1030 | N7: 2930 | O7: 1032 | P7: 2935 | Q7: 1026 | R7: =AVERAGE(J7/K7,L7/M7,N7/O7,P7/Q7)*(48000/H7)*I7*1000 -> 821151.51 | S7: 1.34 | T7: =R7*S7 -> 1100343 | U7: 75480 | V7: 53301 | W7: =V7*I7/H7*1000 -> 319167.66
A8: Hal281-30-5-w0 | B8: Hal281 | C8: Hal281-30-5 | D8: No | E8: self | F8: 7.529 | G8: 0 | H8: 1002 | I8: 6 | J8: 3521 | K8: 1020 | L8: 3451 | M8: 1023 | N8: 3284 | O8: 1026 | P8: 3371 | Q8: 1026 | R8: =AVERAGE(J8/K8,L8/M8,N8/O8,P8/Q8)*(48000/H8)*I8*1000 -> 956531.29 | S8: =1309300/R8 -> 1.3688 | T8: =R8*S8 -> 1309300 | U8: 54928 | V8: 36443 | W8: =V8*I8/H8*1000 -> 218221.56
A9: Hal281-30-5-w2 | B9: Hal281 | C9: Hal281-30-5 | D9: No | E9: self | F9: 7.529 | G9: 2 | H9: 1002 | I9: 6 | J9: 4117 | K9: 1016 | L9: 3921 | M9: 1019 | N9: 3754 | O9: 1010 | P9: 4129 | Q9: 1065 | R9: =AVERAGE(J9/K9,L9/M9,N9/O9,P9/Q9)*(48000/H9)*I9*1000 -> 1113332.9 | S9: 1.37 | T9: =R9*S9 -> 1525266 | U9: 72741 | V9: 51118 | W9: =V9*I9/H9*1000 -> 306095.81
A10: Hal281-30-5-w5 | B10: Hal281 | C10: Hal281-30-5 | D10: No | E10: self | F10: 7.529 | G10: 5 | H10: 1002 | I10: 6 | J10: 3333 | K10: 1006 | L10: 3245 | M10: 1010 | N10: 3118 | O10: 1029 | P10: 3314 | Q10: 1008 | R10: =AVERAGE(J10/K10,L10/M10,N10/O10,P10/Q10)*(48000/H10)*I10*1000 -> 922909.03 | S10: 1.37 | T10: =R10*S10 -> 1264385.4 | U10: 73726 | V10: 51686 | W10: =V10*I10/H10*1000 -> 309497.01
A11: Hal281-30-5-w10 | B11: Hal281 | C11: Hal281-30-5 | D11: No | E11: self | F11: 7.529 | G11: 10 | H11: 1002 | I11: 6 | J11: 2895 | K11: 1016 | L11: 3192 | M11: 1032 | N11: 4369 | O11: 1469 | P11: 3020 | Q11: 1030 | R11: =AVERAGE(J11/K11,L11/M11,N11/O11,P11/Q11)*(48000/H11)*I11*1000 -> 851396.67 | S11: 1.37 | T11: =R11*S11 -> 1166413.4 | U11: 102084 | V11: 72055 | W11: =V11*I11/H11*1000 -> 431467.07
A12: Hal281-30-5-w15 | B12: Hal281 | C12: Hal281-30-5 | D12: No | E12: self | F12: 7.529 | G12: 15 | H12: 1002 | I12: 6 | J12: 2932 | K12: 1028 | L12: 2991 | M12: 1024 | N12: 2946 | O12: 1037 | P12: 3399 | Q12: 1198 | R12: =AVERAGE(J12/K12,L12/M12,N12/O12,P12/Q12)*(48000/H12)*I12*1000 -> 822837.44 | S12: 1.37 | T12: =R12*S12 -> 1127287.3 | U12: 79449 | V12: 57776 | W12: =V12*I12/H12*1000 -> 345964.07
A13: Hal281-30-5-w30 | B13: Hal281 | C13: Hal281-30-5 | D13: No | E13: self | F13: 7.529 | G13: 30 | H13: 1002 | I13: 6 | J13: 2266 | K13: 1017 | L13: 2556 | M13: 1009 | N13: 2424 | O13: 1013 | P13: 2292 | Q13: 1017 | R13: =AVERAGE(J13/K13,L13/M13,N13/O13,P13/Q13)*(48000/H13)*I13*1000 -> 676016.97 | S13: 1.37 | T13: =R13*S13 -> 926143.25 | U13: 77193 | V13: 55123 | W13: =V13*I13/H13*1000 -> 330077.84
A14: Hal281-30-6-w0 | B14: Hal281 | C14: Hal281-30-6 | D14: No | E14: self | F14: 5.739 | G14: 0 | H14: 1002 | I14: 6 | J14: 3648 | K14: 1006 | L14: 3768 | M14: 1007 | N14: 3625 | O14: 1009 | P14: 3454 | Q14: 1012 | R14: =AVERAGE(J14/K14,L14/M14,N14/O14,P14/Q14)*(48000/H14)*I14*1000 -> 1032845 | S14: =1309300/R14 -> 1.2676636 | T14: =R14*S14 -> 1309300 | U14: 58999 | V14: 42085 | W14: =V14*I14/H14*1000 -> 252005.99
A15: Hal281-30-6-w2 | B15: Hal281 | C15: Hal281-30-6 | D15: No | E15: self | F15: 5.739 | G15: 2 | H15: 1002 | I15: 6 | J15: 4026 | K15: 1043 | L15: 3662 | M15: 1014 | N15: 3885 | O15: 1035 | P15: 3765 | Q15: 1009 | R15: =AVERAGE(J15/K15,L15/M15,N15/O15,P15/Q15)*(48000/H15)*I15*1000 -> 1074718.5 | S15: 1.27 | T15: =R15*S15 -> 1364892.5 | U15: 71769 | V15: 50113 | W15: =V15*I15/H15*1000 -> 300077.84
A16: Hal281-30-6-w5 | B16: Hal281 | C16: Hal281-30-6 | D16: No | E16: self | F16: 5.739 | G16: 5 | H16: 1002 | I16: 6 | J16: 3307 | K16: 1027 | L16: 3730 | M16: 1080 | N16: 3210 | O16: 1014 | P16: 3382 | Q16: 1029 | R16: =AVERAGE(J16/K16,L16/M16,N16/O16,P16/Q16)*(48000/H16)*I16*1000 -> 943194.88 | S16: 1.27 | T16: =R16*S16 -> 1197857.5 | U16: 67559 | V16: 47811 | W16: =V16*I16/H16*1000 -> 286293.41
A17: Hal281-30-6-w10 | B17: Hal281 | C17: Hal281-30-6 | D17: No | E17: self | F17: 5.739 | G17: 10 | H17: 1002 | I17: 6 | J17: 3455 | K17: 1042 | L17: 3233 | M17: 1014 | N17: 3164 | O17: 1014 | P17: 3277 | Q17: 1026 | R17: =AVERAGE(J17/K17,L17/M17,N17/O17,P17/Q17)*(48000/H17)*I17*1000 -> 921080.81 | S17: 1.27 | T17: =R17*S17 -> 1169772.6 | U17: 61356 | V17: 44804 | W17: =V17*I17/H17*1000 -> 268287.43
A18: Hal281-30-6-w15 | B18: Hal281 | C18: Hal281-30-6 | D18: No | E18: self | F18: 5.739 | G18: 15 | H18: 1002 | I18: 6 | J18: 3169 | K18: 1015 | L18: 3248 | M18: 1020 | N18: 3156 | O18: 1010 | P18: 3130 | Q18: 1043 | R18: =AVERAGE(J18/K18,L18/M18,N18/O18,P18/Q18)*(48000/H18)*I18*1000 -> 893331.19 | S18: 1.27 | T18: =R18*S18 -> 1134530.6 | U18: 69302 | V18: 50468 | W18: =V18*I18/H18*1000 -> 302203.59
A19: Hal281-30-6-w30 | B19: Hal281 | C19: Hal281-30-6 | D19: No | E19: self | F19: 5.739 | G19: 30 | H19: 1002 | I19: 6 | J19: 2636 | K19: 1031 | L19: 2719 | M19: 1035 | N19: 2875 | O19: 1023 | P19: 2741 | Q19: 1077 | R19: =AVERAGE(J19/K19,L19/M19,N19/O19,P19/Q19)*(48000/H19)*I19*1000 -> 757306.95 | S19: 1.27 | T19: =R19*S19 -> 961779.82 | U19: 70866 | V19: 51439 | W19: =V19*I19/H19*1000 -> 308017.96
A20: Hal281-60-4-w0 | B20: Hal281 | C20: Hal281-60-4 | D20: No | E20: self | F20: 4.227 | G20: 0 | H20: 1002 | I20: 6 | J20: 3829 | K20: 1033 | L20: 5114 | M20: 1343 | N20: 4695 | O20: 1234 | P20: 5119 | Q20: 1530 | R20: =AVERAGE(J20/K20,L20/M20,N20/O20,P20/Q20)*(48000/H20)*I20*1000 -> 1053774.2 | S20: =1309300/R20 -> 1.2424863 | T20: =R20*S20 -> 1309300 | U20: 73191 | V20: 55586 | W20: =V20*I20/H20*1000 -> 332850.3
A21: Hal281-60-4-w2 | B21: Hal281 | C21: Hal281-60-4 | D21: No | E21: self | F21: 4.227 | G21: 2 | H21: 1002 | I21: 6 | J21: 3492 | K21: 1018 | L21: 3448 | M21: 1031 | N21: 3414 | O21: 1019 | P21: 3302 | Q21: 1009 | R21: =AVERAGE(J21/K21,L21/M21,N21/O21,P21/Q21)*(48000/H21)*I21*1000 -> 962692.59 | S21: 1.24 | T21: =R21*S21 -> 1193738.8 | U21: 59743 | V21: 40996 | W21: =V21*I21/H21*1000 -> 245485.03
A22: Hal281-60-4-w5 | B22: Hal281 | C22: Hal281-60-4 | D22: No | E22: self | F22: 4.227 | G22: 5 | H22: 1002 | I22: 6 | J22: 3395 | K22: 1011 | L22: 3398 | M22: 1015 | N22: 3217 | O22: 1014 | P22: 3348 | Q22: 1010 | R22: =AVERAGE(J22/K22,L22/M22,N22/O22,P22/Q22)*(48000/H22)*I22*1000 -> 948020.11 | S22: 1.24 | T22: =R22*S22 -> 1175544.9 | U22: 54644 | V22: 35324 | W22: =V22*I22/H22*1000 -> 211520.96
A23: Hal281-60-4-w10 | B23: Hal281 | C23: Hal281-60-4 | D23: No | E23: self | F23: 4.227 | G23: 10 | H23: 1002 | I23: 6 | J23: 3367 | K23: 1029 | L23: 3406 | M23: 1018 | N23: 3315 | O23: 1026 | P23: 3309 | Q23: 1016 | R23: =AVERAGE(J23/K23,L23/M23,N23/O23,P23/Q23)*(48000/H23)*I23*1000 -> 941731.89 | S23: 1.24 | T23: =R23*S23 -> 1167747.5 | U23: 58749 | V23: 39847 | W23: =V23*I23/H23*1000 -> 238604.79
A24: Hal281-60-4-w15 | B24: Hal281 | C24: Hal281-60-4 | D24: No | E24: self | F24: 4.227 | G24: 15 | H24: 1002 | I24: 6 | J24: 3124 | K24: 1009 | L24: 3075 | M24: 1008 | N24: 2971 | O24: 1027 | P24: 3106 | Q24: 1026 | R24: =AVERAGE(J24/K24,L24/M24,N24/O24,P24/Q24)*(48000/H24)*I24*1000 -> 867083.53 | S24: 1.24 | T24: =R24*S24 -> 1075183.6 | U24: 67214 | V24: 48609 | W24: =V24*I24/H24*1000 -> 291071.86
A25: Hal281-60-4-w30 | B25: Hal281 | C25: Hal281-60-4 | D25: No | E25: self | F25: 4.227 | G25: 30 | H25: 1002 | I25: 6 | J25: 2429 | K25: 1022 | L25: 2462 | M25: 1080 | N25: 2506 | O25: 1079 | P25: 2315 | Q25: 1010 | R25: =AVERAGE(J25/K25,L25/M25,N25/O25,P25/Q25)*(48000/H25)*I25*1000 -> 666175.47 | S25: 1.24 | T25: =R25*S25 -> 826057.59 | U25: 78554 | V25: 49206 | W25: =V25*I25/H25*1000 -> 294646.71
A26: Hal281-60-4-w45 | B26: Hal281 | C26: Hal281-60-4 | D26: No | E26: self | F26: 4.227 | G26: 45 | H26: 1000 | I26: 2 | J26: NA | K26: NA | L26: 3698 | M26: 1005 | N26: 3954 | O26: 1011 | P26: 3976 | Q26: 1015 | R26: =AVERAGE(L26/M26,N26/O26,P26/Q26)*(48000/H26)*I26*1000 -> 368250.32 | S26: 1.24 | T26: =R26*S26 -> 456630.4 | U26: 199409 | V26: 187023 | W26: =V26*I26/H26*1000 -> 374046
A27: Hal281-60-4-w60 | B27: Hal281 | C27: Hal281-60-4 | D27: No | E27: self | F27: 4.227 | G27: 60 | H27: 1000 | I27: 2 | J27: NA | K27: NA | L27: 4084 | M27: 1009 | N27: 3724 | O27: 1012 | P27: 3851 | Q27: 1010 | R27: =AVERAGE(L27/M27,N27/O27,P27/Q27)*(48000/H27)*I27*1000 -> 369289.12 | S27: 1.24 | T27: =R27*S27 -> 457918.51 | U27: 211648 | V27: 199552 | W27: =V27*I27/H27*1000 -> 399104
A28: Hal281-60-5-w0 | B28: Hal281 | C28: Hal281-60-5 | D28: No | E28: self | F28: 3.877 | G28: 0 | H28: 1002 | I28: 6 | J28: 4503 | K28: 1014 | L28: 4290 | M28: 1017 | N28: 4283 | O28: 1023 | P28: 4382 | Q28: 1021 | R28: =AVERAGE(J28/K28,L28/M28,N28/O28,P28/Q28)*(48000/H28)*I28*1000 -> 1231451.1 | S28: =1309300/R28 -> 1.0632172 | T28: =R28*S28 -> 1309300 | U28: 46798 | V28: 29457 | W28: =V28*I28/H28*1000 -> 176389.22
A29: Hal281-60-5-w2 | B29: Hal281 | C29: Hal281-60-5 | D29: No | E29: self | F29: 3.877 | G29: 2 | H29: 1002 | I29: 6 | J29: 4431 | K29: 1006 | L29: 4224 | M29: 1016 | N29: 4740 | O29: 1020 | P29: 4518 | Q29: 1014 | R29: =AVERAGE(J29/K29,L29/M29,N29/O29,P29/Q29)*(48000/H29)*I29*1000 -> 1269322.1 | S29: 1.06 | T29: =R29*S29 -> 1345481.5 | U29: 70698 | V29: 47170 | W29: =V29*I29/H29*1000 -> 282455.09
A30: Hal281-60-5-w5 | B30: Hal281 | C30: Hal281-60-5 | D30: No | E30: self | F30: 3.877 | G30: 5 | H30: 1002 | I30: 6 | J30: 4207 | K30: 1007 | L30: 4361 | M30: 1010 | N30: 4343 | O30: 1011 | P30: 4393 | Q30: 1011 | R30: =AVERAGE(J30/K30,L30/M30,N30/O30,P30/Q30)*(48000/H30)*I30*1000 -> 1231367.2 | S30: 1.06 | T30: =R30*S30 -> 1305249.2 | U30: 59730 | V30: 40631 | W30: =V30*I30/H30*1000 -> 243299.4
A31: Hal281-60-5-w10 | B31: Hal281 | C31: Hal281-60-5 | D31: No | E31: self | F31: 3.877 | G31: 10 | H31: 1002 | I31: 6 | J31: 3994 | K31: 999 | L31: 4270 | M31: 1047 | N31: 4328 | O31: 1017 | P31: 3850 | Q31: 1020 | R31: =AVERAGE(J31/K31,L31/M31,N31/O31,P31/Q31)*(48000/H31)*I31*1000 -> 1157351.9 | S31: 1.06 | T31: =R31*S31 -> 1226793 | U31: 62726 | V31: 41246 | W31: =V31*I31/H31*1000 -> 246982.04
A32: Hal281-60-5-w15 | B32: Hal281 | C32: Hal281-60-5 | D32: No | E32: self | F32: 3.877 | G32: 15 | H32: 1002 | I32: 6 | J32: 3917 | K32: 1014 | L32: 4245 | M32: 1010 | N32: 4193 | O32: 1073 | P32: 3793 | Q32: 1015 | R32: =AVERAGE(J32/K32,L32/M32,N32/O32,P32/Q32)*(48000/H32)*I32*1000 -> 1128903.3 | S32: 1.06 | T32: =R32*S32 -> 1196637.5 | U32: 73559 | V32: 49514 | W32: =V32*I32/H32*1000 -> 296491.02
A33: Hal281-60-5-w30 | B33: Hal281 | C33: Hal281-60-5 | D33: No | E33: self | F33: 3.877 | G33: 30 | H33: 1002 | I33: 6 | J33: 3649 | K33: 1011 | L33: 3514 | M33: 1021 | N33: 3261 | O33: 1024 | P33: 3223 | Q33: 1010 | R33: =AVERAGE(J33/K33,L33/M33,N33/O33,P33/Q33)*(48000/H33)*I33*1000 -> 964791.45 | S33: 1.06 | T33: =R33*S33 -> 1022678.9 | U33: 58988 | V33: 40626 | W33: =V33*I33/H33*1000 -> 243269.46
A34: Hal281-60-5-w45 | B34: Hal281 | C34: Hal281-60-5 | D34: No | E34: self | F34: 3.877 | G34: 45 | H34: 1000 | I34: 2 | J34: NA | K34: NA | L34: 5465 | M34: 1044 | N34: 5287 | O34: 1032 | P34: 5708 | Q34: 1015 | R34: =AVERAGE(L34/M34,N34/O34,P34/Q34)*(48000/H34)*I34*1000 -> 511404.21 | S34: 1.06 | T34: =R34*S34 -> 542088.47 | U34: 183714 | V34: 170765 | W34: =V34*I34/H34*1000 -> 341530
